<?xml version="1.0"?>
<robot name="x-agrobort-pheno">

	<!-- Robot Footprint -->
  	<link name="base_footprint"/>
  	
  	<joint name="base_joint" type="fixed">
    		<parent link="base_footprint"/>
    		<child link="base_link"/>
    		<origin xyz="0.17 0.0 0.263" rpy="0 0 0"/>
  	</joint>
  	
	<!--base link -->
	<link name="base_link">
		<visual>
		<origin xyz="0 0 0.0" rpy="0 0 0"/>
		<geometry>
			<box size="0.43 0.33 0.4"/>
		</geometry>
		<material name="blue"> 
			<color rgba="0.1 0.1 1.0 0.3" /> 
		</material>
		</visual>
		<collision>
      			<origin xyz="0 0 0.0" rpy="0 0 0"/>
      			<geometry>
        			<box size="0.43 0.33 0.4"/>
      			</geometry>
      			<material name="blue">
          			<color rgba="1.0 0.1 0.1 0.3" /> 
      			</material>
    		</collision>
    		<inertial>
      			<mass value="40"/>
      			<inertia ixx="1.54" ixy="0" ixz="0" iyy="1.73" iyz="0" izz="1.25"/>
    		</inertial>
	</link>
	
	<!-- laser link -->
	<link name="laser">
		<visual>
		<origin xyz="0 0 0" rpy="0 0 0"/>
		<geometry>
			<cylinder length="0.02" radius="0.02"/>
		</geometry>
		<material name="black">
			<color rgba="0.0 0.0 0.0 0.8" /> 	
		</material>
		</visual>
		<collision>
      			<origin xyz="0 0 0" rpy="0 0 0"/>
      			<geometry>
        			<cylinder length="0.02" radius="0.02"/>
      			</geometry>
      			<material name="black">
        			<color rgba="0.0 0.0 0.0 0.5" /> 
      			</material>
    		</collision>
    		<inertial>
    			<mass value="0.1"/>
      			<inertia ixx="0.000190416666667" ixy="0" ixz="0" iyy="0.0001904" iyz="0" izz="0.00036"/>
    		</inertial>
	</link>
	
	<!-- laser joint -->
	<joint name="laser_joint" type="fixed">
        	<parent link="base_link" />
        	<child link="laser" />
        	<origin xyz="0.18 0 0.17" rpy="3.14 0 3.14" />
    	</joint>
    	
    	<link name="right_wheel_link">
    		<visual>
        	<origin xyz="0 0 0" rpy="1.57079 0 0"/>
        	<geometry>
          		<cylinder length="0.045" radius="0.085"/>
        	</geometry>
          	<material name="black">
            		<color rgba="0.0 0.0 0.0 0.5" /> 
          	</material>
      		</visual>
      		<collision>
        		<origin xyz="0 0 0" rpy="1.57079 0 0"/>
        		<geometry>
          			<cylinder length="0.045" radius="0.085"/>
        		</geometry>
          		<material name="black">
            			<color rgba="0.0 0.0 0.0 0.5" /> 
         		</material>
      		</collision>
      		<inertial>
      			<mass value="0.2"/>
     			<inertia ixx="0.000190416666667" ixy="0" ixz="0" iyy="0.0001904" iyz="0" izz="0.00036"/>
    		</inertial>
  	</link>
  	
  	<joint name="right_wheel_joint" type="continuous">
      		<parent link="base_link" />
      		<child link="right_wheel_link" />
      		<origin xyz="-0.17 -0.175 -0.178" />
      		<axis xyz="0 1 0" />
  	</joint>
  	
  	<link name="left_wheel_link">
      		<visual>
        	<origin xyz="0 0 0" rpy="1.57079 0 0"/>
        	<geometry>
          		<cylinder length="0.045" radius="0.085"/>
        	</geometry>
         	<material name="black">
            		<color rgba="0.0 0.0 0.0 0.5" /> 
          	</material>
      		</visual>
      		<collision>
        		<origin xyz="0 0 0" rpy="1.57079 0 0"/>
        		<geometry>
          			<cylinder length="0.045" radius="0.085"/>
        		</geometry>
          		<material name="black">
            			<color rgba="0.0 0.0 0.0 0.5" /> 
          		</material>
      		</collision>
      		<inertial>
        		<mass value="0.2"/>
          		<inertia ixx="0.000190416666667" ixy="0" ixz="0" iyy="0.0001904" iyz="0" izz="0.00036"/>
        	</inertial>
  	</link>
    
  	<joint name="left_wheel_joint" type="continuous">
      		<parent link="base_link" />
      		<child link="left_wheel_link" />
      		<origin xyz="-0.17 0.175 -0.178" />
      		<axis xyz="0 1 0" />
  	</joint>
  	
  	<link name="left_caster_link">
    		<visual>
      		<origin xyz="0 0 0" rpy="1.57079 0 0"/>
      		<geometry>
          		<cylinder length="0.02" radius="0.0315"/>
      		</geometry>
        	<material name="black">
          		<color rgba="0.0 0.0 0.0 0.5" /> 
        	</material>
    		</visual>
    		<collision>
        		<origin xyz="0 0 0" rpy="1.57079 0 0"/>
        		<geometry>
            			<cylinder length="0.02" radius="0.0315"/>
        		</geometry>
          		<material name="black">
            			<color rgba="0.0 0.0 0.0 0.5" /> 
          		</material>
      		</collision>
      		<inertial>
      			<mass value="0.02"/>
      			<inertia ixx="0.000190416666667" ixy="0" ixz="0" iyy="0.0001904" iyz="0" izz="0.00036"/>
    		</inertial>
  	</link>
    
  	<joint name="left_caster_joint" type="fixed">
      		<parent link="base_link" />
      		<child link="left_caster_link" />
      		<origin xyz="0.2 0.1435 -0.2315" />
      		<axis xyz="0 1 0"/>
  	</joint>

  	<link name="right_caster_link">
    		<visual>
      		<origin xyz="0 0 0" rpy="1.57079 0 0"/>
      		<geometry>
          		<cylinder length="0.02" radius="0.0315"/>
      		</geometry>
        	<material name="black">
          		<color rgba="0.0 0.0 0.0 0.5" /> 
        	</material>
    		</visual>
    		    		<collision>
        		<origin xyz="0 0 0" rpy="1.57079 0 0"/>
        		<geometry>
            			<cylinder length="0.02" radius="0.0315"/>
        		</geometry>
          		<material name="black">
            			<color rgba="0.0 0.0 0.0 0.5" /> 
          		</material>
      		</collision>
      		<inertial>
      			<mass value="0.02"/>
      			<inertia ixx="0.000190416666667" ixy="0" ixz="0" iyy="0.0001904" iyz="0" izz="0.00036"/>
    		</inertial>
  	</link>
    
  	<joint name="right_caster_joint" type="fixed">
      		<parent link="base_link" />
      		<child link="right_caster_link" />
      		<origin xyz="0.2 -0.1435 -0.2315" />
      		<axis xyz="0 0 0"/>
  	</joint>
  	
  	
  	
  	<gazebo reference="left_caster_link">
    		<material>Gazebo/Black</material>
  	</gazebo>
  	
  	<gazebo reference="right_caster_link">
    		<material>Gazebo/Black</material>
  	</gazebo>
	
	<gazebo reference="left_caster_link">
    		<mu1 value="0.1"/>
    		<mu2 value="0.1"/>
    		<kp value="1000000.0" />
    		<kd value="5.0" />
    		<!-- <fdir1 value="0 0 1"/> -->
  	</gazebo>
  	
  	<gazebo reference="right_caster_link">
    		<mu1 value="0.1"/>
    		<mu2 value="0.1"/>
    		<kp value="1000000.0" />
    		<kd value="5.0" />
    		<!-- <fdir1 value="0 0 1"/> -->
  	</gazebo>
  	
  	<gazebo>
    		<plugin name='diff_drive' filename='libgazebo_ros_diff_drive.so'>
			<ros>
				<namespace>/</namespace>
				<remapping>cmd_vel:=cmd_vel</remapping>
				<remapping>odom:=odom</remapping>
			</ros>
			<update_rate>30</update_rate>
			<!-- wheels -->
			<left_joint>left_wheel_joint</left_joint>
			<right_joint>right_wheel_joint</right_joint>
			<!-- kinematics -->
			<wheel_separation>0.2</wheel_separation>
			<wheel_diameter>0.065</wheel_diameter>
			<!-- limits -->
			<max_wheel_torque>20</max_wheel_torque>
			<max_wheel_acceleration>1.0</max_wheel_acceleration>
			<!-- output -->
			<publish_odom>true</publish_odom>
			<publish_odom_tf>true</publish_odom_tf>
			<publish_wheel_tf>true</publish_wheel_tf>
			<odometry_frame>odom</odometry_frame>
			<robot_base_frame>base_footprint</robot_base_frame>
	      	</plugin>
	      
	      	<plugin name="fishbot_joint_state" filename="libgazebo_ros_joint_state_publisher.so">
			<ros>
				<remapping>~/out:=joint_states</remapping>
			</ros>
			<update_rate>30</update_rate>
			<joint_name>right_wheel_joint</joint_name>
			<joint_name>left_wheel_joint</joint_name>
		</plugin>	
	</gazebo> 
	
	<gazebo reference="laser">
		<material>Gazebo/Black</material>
	</gazebo>
	
	<gazebo reference="laser">
		<sensor name="laser_sensor" type="ray">
		<always_on>true</always_on>
		<visualize>true</visualize>
	      	<update_rate>10</update_rate>
	      	<pose>0 0 0.4 0 0 0</pose>
	      	<ray>
			<scan>
		    		<horizontal>
		      			<samples>180</samples>
		      			<resolution>1.000000</resolution>
		      			<min_angle>-1.57</min_angle>
		      			<max_angle>1.57</max_angle>
		   		</horizontal>
		  	</scan>
		  	<range>
					<min>0.120000</min>
					<max>3.5</max>
					<resolution>0.015000</resolution>
		  	</range>
		  	<noise>
					<type>gaussian</type>
					<mean>0.0</mean>
					<stddev>0.01</stddev>
		  	</noise>
	      	</ray>

		<plugin name="laserscan" filename="libgazebo_ros_ray_sensor.so">
			<ros>
		  		<remapping>~/out:=scan</remapping>
			</ros>
			<output_type>sensor_msgs/LaserScan</output_type>
			<frame_name>laser</frame_name>
	      	</plugin>
	      	</sensor>
    	</gazebo>
</robot>
